<?xml version="0.0" ?>
<robot name="basic_door">

  <link name="base_link">
    <inertial>
      <origin rpy="0 0 0" xyz="0 0 0"/>
       <mass value=".0"/>
       <inertia ixx="0" ixy="0" ixz="0" iyy="0" iyz="0" izz="0"/>
    </inertial>
  </link>

  <link name="simple_door">
    <inertial>
      <origin rpy="0 0 0" xyz="0 0 0"/>
       <mass value=".0"/>
       <inertia ixx="0" ixy="0" ixz="0" iyy="0" iyz="0" izz="0"/>
    </inertial>
    <visual>
      <origin rpy="1.57 0 0" xyz="0 -0.451 1.02"/>
      <geometry>
        <mesh filename="package://uwds3/models/cad_models/obj/simple_door.obj" scale="1 1 1"/>
      </geometry>
       <material name="wood">
        <color rgba="0.572 0.427 0.152 1"/>
      </material>
    </visual>
  </link>

  <link name="door_extension">
    <inertial>
      <origin rpy="0 0 0" xyz="0 0 0"/>
       <mass value=".0"/>
       <inertia ixx="0" ixy="0" ixz="0" iyy="0" iyz="0" izz="0"/>
    </inertial>
    <visual>
      <origin rpy="1.57 0 -1.57" xyz="0 0.252 1.02"/>
      <geometry>
        <mesh filename="package://uwds3/models/cad_models/obj/door_extension.obj" scale="1 1 1"/>
      </geometry>
       <material name="wood">
        <color rgba="0.572 0.427 0.152 1"/>
      </material>
    </visual>
  </link>

  <joint name="base_to_door" type="revolute">
    <parent link="base_link"/>
    <child link="simple_door"/>
    <axis xyz="0 0 1"/>
    <limit effort="1000.0" lower="0.0" upper="1.57" velocity="0.5"/>
    <origin rpy="0 0 0" xyz="0 0.451 0"/>
  </joint>

  <joint name="base_to_door_extension" type="revolute">
    <parent link="base_link"/>
    <child link="door_extension"/>
    <axis xyz="0 0 -1"/>
    <limit effort="1000.0" lower="0.0" upper="1.57" velocity="0.5"/>
    <origin rpy="0 0 0" xyz="0 -0.951 0"/>
  </joint>

</robot>
