<?xml version="0.0" ?>
<robot name="door_h20">

  <link name="base_link">
    <inertial>
      <origin rpy="0 0 0" xyz="0 0 0"/>
       <mass value=".0"/>
       <inertia ixx="0" ixy="0" ixz="0" iyy="0" iyz="0" izz="0"/>
    </inertial>
    <visual>
      <origin rpy="1.57 0 0" xyz="0 0 1.059"/>
      <geometry>
				<mesh filename="package://uwds3/models/cad_models/obj/door_h20.obj" scale="1 1 1"/>
      </geometry>
       <material name="white">
        <color rgba="1 1 1 1"/>
      </material>
    </visual>
  </link>

  <link name="door_h20_1">
    <inertial>
      <origin rpy="0 0 0" xyz="0 0 0"/>
       <mass value=".0"/>
       <inertia ixx="0" ixy="0" ixz="0" iyy="0" iyz="0" izz="0"/>
    </inertial>
    <visual>
      <origin rpy="1.57 0 0" xyz="0 0.459 1.02"/>
      <geometry>
        <mesh filename="package://uwds3/models/cad_models/obj/door_h20_1.obj" scale="1 1 1"/>
      </geometry>
       <material name="wood">
        <color rgba="0.572 0.427 0.152 1"/>
      </material>
    </visual>
  </link>

  <link name="door_h20_2">
    <inertial>
      <origin rpy="0 0 0" xyz="0 0 0"/>
       <mass value=".0"/>
       <inertia ixx="0" ixy="0" ixz="0" iyy="0" iyz="0" izz="0"/>
    </inertial>
    <visual>
      <origin rpy="1.57 0 0" xyz="0 -0.459 1.02"/>
      <geometry>
        <mesh filename="package://uwds3/models/cad_models/obj/door_h20_2.obj" scale="1 1 1"/>
      </geometry>
       <material name="wood">
        <color rgba="0.572 0.427 0.152 1"/>
      </material>
    </visual>
  </link>

  <joint name="base_to_door_1" type="revolute">
    <parent link="base_link"/>
    <child link="door_h20_1"/>
    <axis xyz="0 0 -1"/>
    <limit effort="1000.0" lower="0.0" upper="1.57" velocity="0.5"/>
    <origin rpy="0 0 0" xyz="0 -0.918 0"/>
  </joint>

  <joint name="base_to_door_2" type="revolute">
    <parent link="base_link"/>
    <child link="door_h20_2"/>
    <axis xyz="0 0 1"/>
    <limit effort="1000.0" lower="0.0" upper="1.57" velocity="0.5"/>
    <origin rpy="0 0 0" xyz="0 0.918 0"/>
  </joint>

</robot>
