<?xml version="0.0" ?>
<robot name="elevator_1">

  <link name="base_link">
    <inertial>
      <origin rpy="0 0 0" xyz="0 0 0"/>
       <mass value=".0"/>
       <inertia ixx="0" ixy="0" ixz="0" iyy="0" iyz="0" izz="0"/>
    </inertial>
    <visual>
      <origin rpy="0 0 0" xyz="0 0 1"/>
      <geometry>
				<box size="1.1 1.467 2"/>
      </geometry>
      <material name="black_metal">
       <color rgba="0.4 0.4 0.4 1"/>
     </material>
    </visual>
  </link>

  <link name="elevator">
    <inertial>
      <origin rpy="0 0 0" xyz="0 0 0"/>
       <mass value=".0"/>
       <inertia ixx="0" ixy="0" ixz="0" iyy="0" iyz="0" izz="0"/>
    </inertial>
    <visual>
      <origin rpy="1.57 0 0" xyz="0 0 1.0485"/>
      <geometry>
        <mesh filename="package://adream_simulation/models/cad_models/obj/elevator_1.obj" scale="1 0.9 1"/>
      </geometry>
       <material name="black_metal">
        <color rgba="0.4 0.4 0.4 1"/>
      </material>
    </visual>
  </link>

  <joint name="base_to_elevator" type="prismatic">
    <parent link="base_link"/>
    <child link="elevator"/>
    <axis xyz="0 0 1"/>
    <limit effort="1000.0" lower="0" upper="4" velocity="0.5"/>
    <origin rpy="0 0 0" xyz="0 0 0"/>
  </joint>

</robot>
