<?xml version="1.0" ?>
<!-- =================================================================================== -->
<!-- |    This document was autogenerated by xacro from human.xacro                    | -->
<!-- |    EDITING THIS FILE BY HAND IS NOT RECOMMENDED                                 | -->
<!-- =================================================================================== -->
<robot name="kinect" xmlns:xacro="http://www.ros.org/wiki/xacro">

  <material name="metal">
    <color rgba="0.9 0.9 0.9 1"/>
  </material>

  <material name="black_plastic">
    <color rgba="0.2 0.2 0.2 1"/>
  </material>

  <!-- Links: inertial,visual,collision -->
  <link name="base_link">
    <inertial>
      <origin nrpy="0 0 0" xyz="0 0 0"/>
      <mass value="5"/>
      <inertia ixx="5" ixy="0" ixz="0" iyy="5" iyz="0" izz="5"/>
    </inertial>

    <visual>
      <origin xyz="0 0 0.05"/>
      <geometry>
        <cylinder radius="0.3" length=".1"/>
      </geometry>
      <material name="black_plastic"/>
    </visual>
    <collision>
      <!-- origin is relative -->
      <origin xyz="0 0 0.05"/>
      <geometry>
        <cylinder radius="0.3" length=".1"/>
      </geometry>
    </collision>
  </link>

  <link name="base_box">
    <inertial>
      <origin nrpy="0 0 0" xyz="0 0 0"/>
      <mass value="5"/>
      <inertia ixx="5" ixy="0" ixz="0" iyy="5" iyz="0" izz="5"/>
    </inertial>

    <visual>
    	<origin xyz="0 0 0.05"/>
      <geometry>
        <box size="0.25 0.25 0.25"/>
      </geometry>
      <material name="black_plastic"/>
    </visual>
    <collision>
      <!-- origin is relative -->
      <origin xyz="0 0 0.05"/>
      <geometry>
        <box size="0.25 0.25 0.25"/>
      </geometry>
    </collision>
  </link>


  <joint name="base_base_joint" type="fixed">
    <origin rpy="0 0 0" xyz="0 0 0.1"/>
    <child link="base_box"/>
    <parent link="base_link"/>
  </joint>

  <link name="bot_rod">
    <inertial>
      <origin nrpy="0 0 0" xyz="0 0 0"/>
      <mass value="5"/>
      <inertia ixx="5" ixy="0" ixz="0" iyy="5" iyz="0" izz="5"/>
    </inertial>

    <visual>
      <geometry>
        <cylinder radius="0.05" length="1"/>
      </geometry>
      <material name="metal"/>
    </visual>
    <collision>
      <!-- origin is relative -->
      <origin xyz="0 0 0"/>
      <geometry>
        <cylinder radius="0.05" length="1"/>
      </geometry>
    </collision>
  </link>


  <joint name="base_rod" type="fixed">
    <origin rpy="0 0 0" xyz="0 0 0.62"/>
    <child link="bot_rod"/>
    <parent link="base_box"/>
  </joint>

  <link name="top_rod">
    <inertial>
      <origin nrpy="0 0 0" xyz="0 0 0"/>
      <mass value="5"/>
      <inertia ixx="5" ixy="0" ixz="0" iyy="5" iyz="0" izz="5"/>
    </inertial>

    <visual>
      <geometry>
        <cylinder radius="0.05" length="1"/>
      </geometry>
      <material name="metal"/>
    </visual>
    <collision>
      <!-- origin is relative -->
      <origin xyz="0 0 0"/>
      <geometry>
        <cylinder radius="0.05" length="1"/>
      </geometry>
    </collision>
  </link>

  <joint name="rod" type="prismatic">
    <origin rpy="0 0 0" xyz="0 0 0.3"/>
    <axis xyz="0 0 1"/>
    <limit effort="1000.0" lower="-0.7" upper="0.7" velocity="0.5"/>
    <child link="top_rod"/>
    <parent link="bot_rod"/>
  </joint>


  <link name="top_box">
    <inertial>
      <origin nrpy="0 0 0" xyz="0 0 0"/>
      <mass value="5"/>
      <inertia ixx="5" ixy="0" ixz="0" iyy="5" iyz="0" izz="5"/>
    </inertial>

    <visual>
      <geometry>
        <box size="0.10 0.10 0.15"/>
      </geometry>
      <material name="black_plastic"/>
    </visual>
    <collision>
      <!-- origin is relative -->
      <origin xyz="0 0 0"/>
      <geometry>
        <box size="0.10 0.10 0.15"/>
      </geometry>
    </collision>
  </link>


  <joint name="top_box_rod_joint" type="fixed">
    <origin rpy="0 0 0" xyz="0 0 0.55"/>
    <child link="top_box"/>
    <parent link="top_rod"/>
  </joint>

  <link name="tilt_link">
    <inertial>
      <origin nrpy="0 0 0" xyz="0 0 0"/>
      <mass value="5"/>
      <inertia ixx="5" ixy="0" ixz="0" iyy="5" iyz="0" izz="5"/>
    </inertial>

    <visual>
      <geometry>
        <cylinder radius="0.05" length="0.2"/>
      </geometry>
      <material name="black_plastic"/>
    </visual>
    <collision>
      <!-- origin is relative -->
      <origin xyz="0 0 0"/>
      <geometry>
          <cylinder radius="0.05" length="0.2"/>
      </geometry>
    </collision>
  </link>


  <joint name="tilt_joint" type="revolute">
    <origin rpy="0 1.57079632679 0" xyz="0 0 0.10"/>
    <child link="tilt_link"/>
    <parent link="top_box"/>
    <limit lower="-3.1416" upper="3.1416" effort="10" velocity="3"/>
    <axis xyz="0 0 1"/>
  </joint>


   <joint name="tilt_camera_joint" type="fixed">
    <origin rpy="0 1.57079632679 0" xyz="0 0 0"/>
    <child link="kinect2_link"/>
    <parent link="tilt_link"/>
  </joint>


  <link name="kinect2_link">
    <inertial>
      <origin nrpy="0 0 0" xyz="0 0 0"/>
      <mass value="5"/>
      <inertia ixx="5" ixy="0" ixz="0" iyy="5" iyz="0" izz="5"/>
    </inertial>
  </link>

</robot>
